Workbook
Name BUSCARVV: LAMBDA(IFNA(VLOOKUP('DESCRIPCION BASE'!$A$2,BASE!$A:$J,10,FALSE),""))
Name FUNCIONFECHADEPUBLICACION: LAMBDA(IFNA(XLOOKUP('DESCRIPCION BASE'!$A$2,BASE!$A:$A,BASE!$J:$J),""))

Sheet BASE
A1: id | B1: posicion | C1: Gerencia | D1: ubicacion | E1: Estado | F1: Activa | G1: pdfFileId | H1: UEN | I1: url | J1: fechaPublicacion | K1: Fecha de cierre | L1: Prioridad Empresa | M1: Días de publicación
A2: JOB-2025-000001 | B2: Regional Comercial | C2: Desarrollo Comercial | D2: Corrientes | E2: Activa | F2: TRUE | G2: Corrientes - Regional Comercial (1).pdf | H2: DCAC | I2: =IFERROR(__xludf.DUMMYFUNCTION("G2.url"),"https://drive.google.com/open?id=1l8Q0eQZt8_byy2nd489TZ7B7idptoDL6") -> https://drive.google.com/open?id=1l8Q0eQZt8_byy2nd489TZ7B7idptoDL6 | J2: 46097 | L2: No prioridad Empresa | M2: =IF(OR(K2="",K2>TODAY()),TODAY()-J2,K2-J2) -> 27
A3: JOB-2025-000002 | B3: Regional Comercial | C3: Desarrollo Comercial | D3: La Pampa | E3: Activa | F3: TRUE | G3: La Pampa - Regional Comercial.pdf | H3: DCAC | I3: =IFERROR(__xludf.DUMMYFUNCTION("G3.url"),"https://drive.google.com/open?id=1F9U6Uoe2a3Izrqq7N4KbTau7qNsMkLQi") -> https://drive.google.com/open?id=1F9U6Uoe2a3Izrqq7N4KbTau7qNsMkLQi | J3: 46097 | L3: No prioridad Empresa | M3: =IF(OR(K3="",K3>TODAY()),TODAY()-J3,K3-J3) -> 27
A4: JOB-2025-000003 | B4: Regional Comercial | C4: Desarrollo Comercial | D4: Junin | E4: Activa | F4: TRUE | G4: Junin - Regional Comercial.pdf | H4: DCAC | I4: =IFERROR(__xludf.DUMMYFUNCTION("G4.url"),"https://drive.google.com/open?id=1xbkDWodoJ20DnCYYaEDS90Ja2YlZszkG") -> https://drive.google.com/open?id=1xbkDWodoJ20DnCYYaEDS90Ja2YlZszkG | J4: 46097 | L4: No prioridad Empresa | M4: =IF(OR(K4="",K4>TODAY()),TODAY()-J4,K4-J4) -> 27
A5: JOB-2025-000004 | B5: Regional Comercial | C5: Desarrollo Comercial | D5: Chaco | E5: Activa | F5: TRUE | G5: Chaco - Regional Comercial (1).pdf | H5: DCAC | I5: =IFERROR(__xludf.DUMMYFUNCTION("G5.url"),"https://drive.google.com/open?id=1olNrXEb0uRP_oz0waHdjY3WU_46xgzVK") -> https://drive.google.com/open?id=1olNrXEb0uRP_oz0waHdjY3WU_46xgzVK | J5: 46097 | L5: No prioridad Empresa | M5: =IF(OR(K5="",K5>TODAY()),TODAY()-J5,K5-J5) -> 27
A6: JOB-2025-000005 | B6: Regional Comercial | C6: Desarrollo Comercial | D6: Santa Fe | E6: Activa | F6: TRUE | G6: Santa Fé - Regional Comercial (1).pdf | H6: DCAC | I6: =IFERROR(__xludf.DUMMYFUNCTION("G6.url"),"https://drive.google.com/open?id=1jYkntNdTGfPJiHy93vgOAguoE8XiI40k") -> https://drive.google.com/open?id=1jYkntNdTGfPJiHy93vgOAguoE8XiI40k | J6: 46097 | L6: Prioridad empresa | M6: =IF(OR(K6="",K6>TODAY()),TODAY()-J6,K6-J6) -> 27
A7: JOB-2025-000006 | B7: Analista de Desarrollo Comercial | C7: Desarrollo Comercial | D7: Buenos Aires | E7: Cerrada | F7: FALSE | G7: Analista de Desarrollo Comercial | H7: DCAC | I7: =IFERROR(__xludf.DUMMYFUNCTION("G7.url"),"https://drive.google.com/open?id=1_HsMqdmlRIbUqTR-DK7x0_-oAGe00Amt") -> https://drive.google.com/open?id=1_HsMqdmlRIbUqTR-DK7x0_-oAGe00Amt | J7: 46082 | K7: 46084 | L7: Prioridad empresa | M7: =IF(OR(K7="",K7>TODAY()),TODAY()-J7,K7-J7) -> 2
A8: JOB-2025-000007 | B8: Operador Comercial de Hacienda | C8: Operadores de la mesa | D8: Buenos Aires | E8: Inactiva | F8: FALSE | H8: DCAC | J8: 46097 | M8: =IF(OR(K8="",K8>TODAY()),TODAY()-J8,K8-J8) -> 27
A9: JOB-2025-000008 | B9: Analista de Legales | C9: Administración y Finanzas | D9: Buenos Aires | E9: Activa | F9: TRUE | G9: Búsqueda Analista de Legales (1).pdf | H9: DCAC | I9: =IFERROR(__xludf.DUMMYFUNCTION("G9.url"),"https://drive.google.com/open?id=1OiZybKJo6adgj9UE49khpNGtcOo8uE5I") -> https://drive.google.com/open?id=1OiZybKJo6adgj9UE49khpNGtcOo8uE5I | J9: 46097 | L9: Prioridad empresa | M9: =IF(OR(K9="",K9>TODAY()),TODAY()-J9,K9-J9) -> 27
A10: JOB-2025-000009 | B10: Analista de Finanzas y créditos | C10: Administración y Finanzas | D10: Buenos Aires | E10: Cerrada | F10: FALSE | G10: Búsqueda Analista de Finanzas y Créditos .pdf | H10: DCAC | I10: =IFERROR(__xludf.DUMMYFUNCTION("G10.url"),"https://drive.google.com/open?id=1IqpUOwvapb_zohr0zBNGhV7oku7KjEoO") -> https://drive.google.com/open?id=1IqpUOwvapb_zohr0zBNGhV7oku7KjEoO | J10: 46082 | K10: 46086 | L10: Prioridad empresa | M10: =IF(OR(K10="",K10>TODAY()),TODAY()-J10,K10-J10) -> 4
A11: JOB-2025-000010 | B11: Gerente de Unidad Financiera | C11: Dirección | D11: Buenos Aires | E11: Activa | F11: TRUE | G11: DP. Gerente de Unidad de Negocio (dCP).pdf | H11: DCAC | I11: =IFERROR(__xludf.DUMMYFUNCTION("G11.url"),"https://drive.google.com/open?id=1zPcPLNXgL862TO4hV3tB_ZAl7NEJVsL2") -> https://drive.google.com/open?id=1zPcPLNXgL862TO4hV3tB_ZAl7NEJVsL2 | J11: 46097 | L11: Prioridad empresa | M11: =IF(OR(K11="",K11>TODAY()),TODAY()-J11,K11-J11) -> 27
A12: JOB-2025-000011 | B12: Analista de Operaciones Comerciales | C12: Planificación, soporte y gestión | D12: Buenos Aires | E12: Activa | F12: TRUE | G12: Analista de Operaciones Comerciales.pdf | H12: DCAC | I12: =IFERROR(__xludf.DUMMYFUNCTION("G12.url"),"https://drive.google.com/open?id=1TjUZXJlTvSEmah9HOkhNMoaoH0zq5jvR") -> https://drive.google.com/open?id=1TjUZXJlTvSEmah9HOkhNMoaoH0zq5jvR | J12: 46097 | L12: Prioridad empresa | M12: =IF(OR(K12="",K12>TODAY()),TODAY()-J12,K12-J12) -> 27
A13: JOB-2025-000012 | B13: Analista Contable SR | C13: Administración y Finanzas | D13: Buenos Aires | E13: Cerrada | F13: FALSE | G13: Analista Contable Sr..pdf | H13: DCAC | I13: =IFERROR(__xludf.DUMMYFUNCTION("G13.url"),"https://drive.google.com/open?id=1LQbI7ORA478lNtLZJszL26h2UW5OpFAc") -> https://drive.google.com/open?id=1LQbI7ORA478lNtLZJszL26h2UW5OpFAc | J13: 46002 | K13: 46063 | M13: =IF(OR(K13="",K13>TODAY()),TODAY()-J13,K13-J13) -> 61
A14: JOB-2025-000013 | B14: Analista de At. al Cliente | C14: Planificación, soporte y gestión | D14: Buenos Aires | E14: Cerrada | F14: FALSE | H14: DCAC | J14: 46082 | K14: 46063
A15: JOB-2025-000014 | B15: Analista de Logistica | C15: Planificación, soporte y gestión | D15: Buenos Aires | E15: Cerrada | F15: FALSE | H15: DCAC | J15: 46082 | K15: 46072 | M15: =IF(OR(K15="",K15>TODAY()),TODAY()-J15,K15-J15) -> -10
A16: JOB-2025-000015 | B16: Pasante Machine Learning | C16: Planificación, soporte y gestión | D16: Buenos Aires | E16: Cerrada | F16: FALSE | H16: DCAC | J16: 46082 | K16: 46051 | M16: =IF(OR(K16="",K16>TODAY()),TODAY()-J16,K16-J16) -> -31
A17: JOB-2025-000016 | B17: Regional Comercial | C17: Desarrollo Comercial | D17: Buenos Aires | E17: Activa | F17: TRUE | H17: DCAC | J17: 46097 | L17: No prioridad Empresa | M17: =IF(OR(K17="",K17>TODAY()),TODAY()-J17,K17-J17) -> 27
A18: JOB-2025-000017 | B18: Regional Comercial | C18: Desarrollo Comercial | D18: Santa Fe | E18: Activa | F18: TRUE | H18: DCAC | J18: 46097 | L18: No prioridad Empresa | M18: =IF(OR(K18="",K18>TODAY()),TODAY()-J18,K18-J18) -> 27
A19: JOB-2025-000018 | B19: Regional Comercial | C19: Desarrollo Comercial | D19: Entre Rios | E19: Activa | F19: TRUE | H19: DCAC | J19: 46097 | L19: No prioridad Empresa | M19: =IF(OR(K19="",K19>TODAY()),TODAY()-J20,K19-J20) -> 27
A20: JOB-2025-000019 | B20: Regional Comercial | C20: Desarrollo Comercial | D20: Entre Rios | E20: Activa | F20: TRUE | H20: DCAC | J20: 46097 | L20: No prioridad Empresa | M20: =IF(OR(K20="",K20>TODAY()),TODAY()-J21,K20-J21) -> 27
A21: JOB-2025-000020 | B21: Regional Comercial | C21: Desarrollo Comercial | D21: Cordoba | E21: Activa | F21: TRUE | H21: DCAC | J21: 46097 | L21: No prioridad Empresa | M21: =IF(OR(K21="",K21>TODAY()),TODAY()-#REF!,K21-#REF!) -> #REF!
A22: JOB-2025-000021 | B22: Regional Comercial | C22: Desarrollo Comercial | D22: Salta | E22: Activa | F22: TRUE | H22: DCAC | J22: 46097 | L22: No prioridad Empresa | M22: =IF(OR(K22="",K22>TODAY()),TODAY()-J22,K22-J22) -> 27
A23: JOB-2025-000022 | B23: Regional Comercial | C23: Desarrollo Comercial | D23: Formosa | E23: Activa | F23: TRUE | H23: DCAC | J23: 46097 | L23: No prioridad Empresa | M23: =IF(OR(K23="",K23>TODAY()),TODAY()-J23,K23-J23) -> 27
A24: JOB-2025-000023 | B24: Regional Comercial | C24: Desarrollo Comercial | D24: San Luis | E24: Activa | F24: TRUE | H24: DCAC | J24: 46097 | L24: No prioridad Empresa | M24: =IF(OR(K24="",K24>TODAY()),TODAY()-J24,K24-J24) -> 27
A25: JOB-2025-000024 | B25: Regional Comercial | C25: Desarrollo Comercial | D25: Buenos Aires | E25: Activa | F25: TRUE | H25: DCAC | J25: 46097 | L25: No prioridad Empresa | M25: =IF(OR(K25="",K25>TODAY()),TODAY()-J25,K25-J25) -> 27
A26: JOB-2025-000025 | B26: Regional Comercial | C26: Desarrollo Comercial | D26: Buenos Aires | E26: Activa | F26: TRUE | H26: DCAC | J26: 46097 | L26: No prioridad Empresa | M26: =IF(OR(K26="",K26>TODAY()),TODAY()-J26,K26-J26) -> 27
A27: JOB-2025-000026 | B27: Regional Comercial | C27: Desarrollo Comercial | D27: Buenos Aires | E27: Activa | F27: TRUE | H27: DCAC | J27: 46097 | L27: No prioridad Empresa | M27: =IF(OR(K27="",K27>TODAY()),TODAY()-J27,K27-J27) -> 27
A28: JOB-2025-000027 | B28: Regional Comercial | C28: Desarrollo Comercial | D28: Buenos Aires | E28: Activa | F28: TRUE | H28: DCAC | J28: 46097 | L28: No prioridad Empresa | M28: =IF(OR(K28="",K28>TODAY()),TODAY()-J28,K28-J28) -> 27
A29: JOB-2025-000028 | B29: Regional Comercial | C29: Desarrollo Comercial | D29: Buenos Aires | E29: Activa | F29: TRUE | H29: DCAC | J29: 46097 | L29: No prioridad Empresa | M29: =IF(OR(K29="",K29>TODAY()),TODAY()-J29,K29-J29) -> 27
A30: JOB-2025-000029 | B30: Analista de Mercados | C30: Planificación, soporte y gestión | D30: Buenos Aires | E30: Activa | F30: TRUE | H30: DCAC | J30: 46097 | L30: Prioridad empresa | M30: =IF(OR(K30="",K30>TODAY()),TODAY()-J30,K30-J30) -> 27
A31: JOB-2025-000030 | B31: Analista de Producto Jr. | C31: Desarrollo Tecnológico | D31: Buenos Aires | E31: Activa | F31: TRUE | H31: DCAC | J31: 46097 | L31: Prioridad empresa | M31: =IF(OR(K31="",K31>TODAY()),TODAY()-J31,K31-J31) -> 27
A32: JOB-2025-000031 | B32: Analista de IA | C32: Desarrollo Tecnológico | D32: Buenos Aires | E32: Activa | F32: FALSE | H32: DCAC | J32: 46097 | L32: Prioridad empresa | M32: =IF(OR(K32="",K32>TODAY()),TODAY()-J32,K32-J32) -> 27
A33: JOB-2025-000032 | B33: React Native | C33: Desarrollo Tecnológico | D33: Buenos Aires | E33: Activa | F33: TRUE | H33: DCAC | J33: 46097 | L33: Prioridad empresa | M33: =IF(OR(K33="",K33>TODAY()),TODAY()-J33,K33-J33) -> 27
... A35: JOB-2025-000034 | B35: PHP Developer | C35: Desarrollo Tecnológico | D35: Buenos Aires | E35: Activa | F35: TRUE | H35: DCAC | J35: 46097 | L35: Prioridad empresa | M35: =IF(OR(K35="",K35>TODAY()),TODAY()-J35,K35-J35) -> 27
A36: JOB-2025-000035 | B36: DevOps | C36: Desarrollo Tecnológico | D36: Buenos Aires | E36: Activa | F36: TRUE | H36: DCAC | J36: 46097 | M36: =IF(OR(K36="",K36>TODAY()),TODAY()-J36,K36-J36) -> 27
A37: JOB-2025-000036 | B37: Paid Media | C37: Planificación, soporte y gestión | D37: Buenos Aires | E37: Activa | F37: TRUE | H37: DCAC | J37: 46097 | L37: No prioridad Empresa | M37: =IF(OR(K37="",K37>TODAY()),TODAY()-J37,K37-J37) -> 27
A38: JOB-2025-000037 | B38: Coordinador de Reclutamiento y Selección de Personal | C38: RRHH | D38: Buenos Aires | E38: Activa | F38: TRUE | H38: DCAC | J38: 46097 | L38: Prioridad empresa | M38: =IF(OR(K38="",K38>TODAY()),TODAY()-J38,K38-J38) -> 27
A39: JOB-2025-000038 | B39: Analista de Reclutamiento y Selección de Personal | C39: RRHH | D39: Buenos Aires | E39: Activa | F39: TRUE | H39: DCAC | J39: 46097 | L39: Prioridad empresa | M39: =IF(OR(K39="",K39>TODAY()),TODAY()-J39,K39-J39) -> 27
A40: JOB-2025-000039 | B40: Analista de Atención al Cliente | C40: Planificación, soporte y gestión | D40: Buenos Aires | E40: Activa | F40: TRUE | H40: DCAC | J40: 46097 | L40: No prioridad Empresa | M40: =IF(OR(K40="",K40>TODAY()),TODAY()-J40,K40-J40) -> 27
A41: JOB-2025-000040 | B41: Pasante de Finanzas y Creditos | C41: Administración y Finanzas | D41: Buenos Aires | E41: Activa | F41: TRUE | H41: DCAC | J41: 46097 | L41: Prioridad empresa | M41: =IF(OR(K41="",K41>TODAY()),TODAY()-J41,K41-J41) -> 27
...

Sheet DESCRIPCION BASE
A1: id | B1: posicion | C1: Responsabilidades Principales | D1: Perfil Esperado | E1: Desafios del rol | F1: Habilidades Principales | G1: Propuesta de valor | H1: Ubicación | I1: Modalidad | J1: fechaPublicacion
A2: =BASE!A2 -> JOB-2025-000001 | B2: =BASE!B2 -> Regional Comercial | C2: ✔ Liderar el proceso de compra y venta de hacienda: Serás el punto clave en todo el proceso, desde el contacto inicial hasta la entrega final, gestionando la logística con eficiencia y asegurando que todo funcione sin problemas. ✔ Desarrollar tu zona de influencia: Serás responsable de identificar nuevas oportunidades y expandir nuestra red de clientes, contactando a aquellos que ya están en nuestros prospectos y abriendo nuevas tranqueras. ✔ Cultivar relaciones sólidas: Mantendrás una relación cercana y continua con nuestros clientes, entendiendo sus necesidades y asegurando que cada interacción resulte en una venta exitosa. ✔ Gestión eficiente del sistema: Mantendrás nuestra base de datos actualizada, asegurando que la información sea precisa y que nuestros procesos sean ágiles y efectivos. ✔ Participación activa en marketing: Serás nuestros ojos y oídos en el terreno, siendo una pieza clave en la organización y coordinación de eventos promocionales, ayudándonos a posicionarnos como líderes en el mercado. | D2: ✔ Experiencia mínima de 2 años en comercialización de hacienda bovina (gordos, invernada, cría). ✔ Sólidos conocimientos en ganadería bovina, tipos de categorías, plazos y condiciones de operación. ✔ Perfil comercial proactivo, con excelente manejo de relaciones interpersonales. ✔ Capacidad para detectar oportunidades de negocio, fidelizar clientes y generar nuevos vínculos comerciales. ✔ Conocimiento del mercado ganadero, operadores, consignatarias y zonas de producción. ✔ Autonomía para la gestión comercial integral: desde la captación de operaciones hasta el cierre y seguimiento. ✔ Disponibilidad para viajar. ✔ Se valora cartera de clientes activa o red de contactos en el sector. | E2: ✔ Desarrollar y expandir la cartera de clientes en su zona. ✔ Impulsar la adopción de soluciones digitales en el sector ganadero. ✔ Gestionar de punta a punta las operaciones comerciales. ✔ Generar relaciones de confianza con productores y clientes. ✔ Contribuir al posicionamiento de la compañía en el mercado regional. | F2: ✔Perfil comercial con orientación a resultados. ✔Capacidad de negociación y cierre. ✔Autonomía y proactividad. ✔Buen manejo de relaciones interpersonales. ✔Manejo de herramientas digitales. ✔Conocimiento del mercado ganadero (Excluyente) | H2: Corrientes - Mercedes | I2: Hibrido | J2: =BASE!J2 -> 46097
A3: =BASE!A3 -> JOB-2025-000002 | B3: =BASE!B3 -> Regional Comercial | C3: ✔ Liderar el proceso de compra y venta de hacienda: Serás el punto clave en todo el proceso, desde el contacto inicial hasta la entrega final, gestionando la logística con eficiencia y asegurando que todo funcione sin problemas. ✔ Desarrollar tu zona de influencia: Serás responsable de identificar nuevas oportunidades y expandir nuestra red de clientes, contactando a aquellos que ya están en nuestros prospectos y abriendo nuevas tranqueras. ✔ Cultivar relaciones sólidas: Mantendrás una relación cercana y continua con nuestros clientes, entendiendo sus necesidades y asegurando que cada interacción resulte en una venta exitosa. ✔ Gestión eficiente del sistema: Mantendrás nuestra base de datos actualizada, asegurando que la información sea precisa y que nuestros procesos sean ágiles y efectivos. ✔ Participación activa en marketing: Serás nuestros ojos y oídos en el terreno, siendo una pieza clave en la organización y coordinación de eventos promocionales, ayudándonos a posicionarnos como líderes en el mercado. | D3: ✔ Experiencia mínima de 2 años en comercialización de hacienda bovina (gordos, invernada, cría). Sólidos conocimientos en ganadería bovina, tipos de categorías, plazos y condiciones de operación. ✔ Perfil comercial proactivo, con excelente manejo de relaciones interpersonales. ✔ Capacidad para detectar oportunidades de negocio, fidelizar clientes y generar nuevos vínculos comerciales. ✔ Conocimiento del mercado ganadero, operadores, consignatarias y zonas de producción. ✔ Autonomía para la gestión comercial integral: desde la captación de operaciones hasta el cierre y seguimiento. ✔ Disponibilidad para viajar. ✔ Se valora cartera de clientes activa o red de contactos en el sector. | E3: ✔ Desarrollar y expandir la cartera de clientes en su zona. ✔ Impulsar la adopción de soluciones digitales en el sector ganadero. ✔ Gestionar de punta a punta las operaciones comerciales. ✔ Generar relaciones de confianza con productores y clientes. ✔ Contribuir al posicionamiento de la compañía en el mercado regional. | F3: ✔Perfil comercial con orientación a resultados. ✔Capacidad de negociación y cierre. ✔Autonomía y proactividad. ✔Buen manejo de relaciones interpersonales. ✔Manejo de herramientas digitales. ✔Conocimiento del mercado ganadero (Excluyente) | H3: La Pampa - Realico / Loventue / Rancul | I3: Hibrido | J3: =BASE!J3 -> 46097
A4: =BASE!A4 -> JOB-2025-000003 | B4: =BASE!B4 -> Regional Comercial | C4: ✔ Liderar el proceso de compra y venta de hacienda: Serás el punto clave en todo el proceso, desde el contacto inicial hasta la entrega final, gestionando la logística con eficiencia y asegurando que todo funcione sin problemas. ✔ Desarrollar tu zona de influencia: Serás responsable de identificar nuevas oportunidades y expandir nuestra red de clientes, contactando a aquellos que ya están en nuestros prospectos y abriendo nuevas tranqueras. ✔ Cultivar relaciones sólidas: Mantendrás una relación cercana y continua con nuestros clientes, entendiendo sus necesidades y asegurando que cada interacción resulte en una venta exitosa. ✔ Gestión eficiente del sistema: Mantendrás nuestra base de datos actualizada, asegurando que la información sea precisa y que nuestros procesos sean ágiles y efectivos. ✔ Participación activa en marketing: Serás nuestros ojos y oídos en el terreno, siendo una pieza clave en la organización y coordinación de eventos promocionales, ayudándonos a posicionarnos como líderes en el mercado. | D4: ✔ Experiencia mínima de 2 años en comercialización de hacienda bovina (gordos, invernada, cría). Sólidos conocimientos en ganadería bovina, tipos de categorías, plazos y condiciones de operación. ✔ Perfil comercial proactivo, con excelente manejo de relaciones interpersonales. ✔ Capacidad para detectar oportunidades de negocio, fidelizar clientes y generar nuevos vínculos comerciales. ✔ Conocimiento del mercado ganadero, operadores, consignatarias y zonas de producción. ✔ Autonomía para la gestión comercial integral: desde la captación de operaciones hasta el cierre y seguimiento. ✔ Disponibilidad para viajar. ✔ Se valora cartera de clientes activa o red de contactos en el sector. | E4: ✔ Desarrollar y expandir la cartera de clientes en su zona. ✔ Impulsar la adopción de soluciones digitales en el sector ganadero. ✔ Gestionar de punta a punta las operaciones comerciales. ✔ Generar relaciones de confianza con productores y clientes. ✔ Contribuir al posicionamiento de la compañía en el mercado regional. | F4: ✔Perfil comercial con orientación a resultados. ✔Capacidad de negociación y cierre. ✔Autonomía y proactividad. ✔Buen manejo de relaciones interpersonales. ✔Manejo de herramientas digitales. ✔Conocimiento del mercado ganadero (Excluyente) | H4: Buenos Aires - Junin | I4: Híbrido | J4: =BASE!J4 -> 46097
A5: =BASE!A5 -> JOB-2025-000004 | B5: =BASE!B5 -> Regional Comercial | C5: ✔ Liderar el proceso de compra y venta de hacienda: Serás el punto clave en todo el proceso, desde el contacto inicial hasta la entrega final, gestionando la logística con eficiencia y asegurando que todo funcione sin problemas. ✔ Desarrollar tu zona de influencia: Serás responsable de identificar nuevas oportunidades y expandir nuestra red de clientes, contactando a aquellos que ya están en nuestros prospectos y abriendo nuevas tranqueras. ✔ Cultivar relaciones sólidas: Mantendrás una relación cercana y continua con nuestros clientes, entendiendo sus necesidades y asegurando que cada interacción resulte en una venta exitosa. ✔ Gestión eficiente del sistema: Mantendrás nuestra base de datos actualizada, asegurando que la información sea precisa y que nuestros procesos sean ágiles y efectivos. ✔ Participación activa en marketing: Serás nuestros ojos y oídos en el terreno, siendo una pieza clave en la organización y coordinación de eventos promocionales, ayudándonos a posicionarnos como líderes en el mercado. | D5: ✔Experiencia mínima de 2 años en comercialización de hacienda bovina (gordos, invernada, cría). ✔Sólidos conocimientos en ganadería bovina, tipos de categorías, plazos y condiciones de operación. ✔ Perfil comercial proactivo, con excelente manejo de relaciones interpersonales. ✔ Capacidad para detectar oportunidades de negocio, fidelizar clientes y generar nuevos vínculos comerciales. ✔ Conocimiento del mercado ganadero, operadores, consignatarias y zonas de producción. ✔ Autonomía para la gestión comercial integral: desde la captación de operaciones hasta el cierre y seguimiento. ✔ Disponibilidad para viajar. ✔ Se valora cartera de clientes activa o red de contactos en el sector. | E5: ✔ Desarrollar y expandir la cartera de clientes en su zona. ✔ Impulsar la adopción de soluciones digitales en el sector ganadero. ✔ Gestionar de punta a punta las operaciones comerciales. ✔ Generar relaciones de confianza con productores y clientes. ✔ Contribuir al posicionamiento de la compañía en el mercado regional. | F5: ✔Perfil comercial con orientación a resultados. ✔Capacidad de negociación y cierre. ✔Autonomía y proactividad. ✔Buen manejo de relaciones interpersonales. ✔Manejo de herramientas digitales. ✔Conocimiento del mercado ganadero (Excluyente) | H5: Chaco - Tapenaga / Almirante Brown / Libertador General San Martin | I5: Híbrido | J5: =BASE!J5 -> 46097
A6: =BASE!A6 -> JOB-2025-000005 | B6: =BASE!B6 -> Regional Comercial | C6: ✔ Liderar el proceso de compra y venta de hacienda: Serás el punto clave en todo el proceso, desde el contacto inicial hasta la entrega final, gestionando la logística con eficiencia y asegurando que todo funcione sin problemas. ✔ Desarrollar tu zona de influencia: Serás responsable de identificar nuevas oportunidades y expandir nuestra red de clientes, contactando a aquellos que ya están en nuestros prospectos y abriendo nuevas tranqueras. ✔ Cultivar relaciones sólidas: Mantendrás una relación cercana y continua con nuestros clientes, entendiendo sus necesidades y asegurando que cada interacción resulte en una venta exitosa. ✔ Gestión eficiente del sistema: Mantendrás nuestra base de datos actualizada, asegurando que la información sea precisa y que nuestros procesos sean ágiles y efectivos. ✔ Participación activa en marketing: Serás nuestros ojos y oídos en el terreno, siendo una pieza clave en la organización y coordinación de eventos promocionales, ayudándonos a posicionarnos como líderes en el mercado. | D6: ✔ Experiencia mínima de 2 años en comercialización de hacienda bovina (gordos, invernada, cría). Sólidos conocimientos en ganadería bovina, tipos de categorías, plazos y condiciones de operación. ✔ Perfil comercial proactivo, con excelente manejo de relaciones interpersonales. ✔ Capacidad para detectar oportunidades de negocio, fidelizar clientes y generar nuevos vínculos comerciales. ✔ Conocimiento del mercado ganadero, operadores, consignatarias y zonas de producción. ✔ Autonomía para la gestión comercial integral: desde la captación de operaciones hasta el cierre y seguimiento. ✔ Disponibilidad para viajar. ✔ Se valora cartera de clientes activa o red de contactos en el sector. | E6: ✔ Desarrollar y expandir la cartera de clientes en su zona. ✔ Impulsar la adopción de soluciones digitales en el sector ganadero. ✔ Gestionar de punta a punta las operaciones comerciales. ✔ Generar relaciones de confianza con productores y clientes. ✔ Contribuir al posicionamiento de la compañía en el mercado regional. | F6: ✔Perfil comercial con orientación a resultados. ✔Capacidad de negociación y cierre. ✔Autonomía y proactividad. ✔Buen manejo de relaciones interpersonales. ✔Manejo de herramientas digitales. ✔Conocimiento del mercado ganadero (Excluyente) | H6: Santa Fe - San Cristobal / Vera | I6: Híbrido | J6: =BASE!J6 -> 46097
A7: =BASE!A7 -> JOB-2025-000006 | B7: =BASE!B7 -> Analista de Desarrollo Comercial | C7: ✔ Brindar soporte al desarrollo comercial, colaborando con distintos equipos para asegurar una gestión eficiente. ✔ Elaborar y analizar reportes para la toma de decisiones estratégicas. ✔ Identificar oportunidades de mejora en los procesos existentes y proponer soluciones innovadoras. ✔ Automatizar procesos operativos que actualmente se realizan de forma manual, contribuyendo a una mayor eficiencia y productividad. ✔ Desarrollo de KPIs y métricas. | D7: ✔ Estudiante o graduado de las carreras: Ingeniería, Administración de Empresas o afines ✔ Experiencia en posiciones similares ✔ Conocimientos en Power BI, SQL, Google Sheets, herramientas de visualización | E7: ✔Acompañar el desarrollo del área comercial con foco en eficiencia. ✔Generar información clave para la toma de decisiones. ✔Detectar oportunidades de mejora en procesos internos. ✔Impulsar la automatización de tareas operativas. ✔Desarrollar y dar seguimiento a KPIs del área. | F7: ✔Perfil analítico y orientado a resultados. ✔Manejo de herramientas de análisis de datos. ✔Capacidad de organización y planificación. ✔Proactividad y pensamiento crítico. ✔Orientación a la mejora continua. ✔Buen manejo de herramientas digitales. | G7: ✔ Prepaga de primer nivel ✔ Almuerzo en oficina sin costo ✔ Bonificación del 80% en SportClub ✔ Descuentos exclusivos en Samsung ✔ Club de beneficios | H7: =BASE!D7 -> Buenos Aires | I7: Híbrido | J7: =BASE!J7 -> 46082
A8: =BASE!A8 -> JOB-2025-000007 | B8: =BASE!B8 -> Operador Comercial de Hacienda | H8: =BASE!D8 -> Buenos Aires | I8: Hibrido | J8: =BASE!J8 -> 46097
A9: =BASE!A9 -> JOB-2025-000008 | B9: =BASE!B9 -> Analista de Legales | C9: ✔ Detectar espacios de riesgo y generar acciones preventivas como procesos, alertas, mejoras de seguridad jurídica, etc. ✔ Armar disclaimers para los productos nuevos de digitalización de operaciones, para los servicios de logística tercerizados, etc. ✔ Dar seguimiento y accionar sobre los casos de cobranzas atrasadas, tanto para detectar casos potenciales como para promover acciones de cobro, ya sea preventivas o ejecutivas, como embargos o lo que proceda según el caso. ✔ Revisar y redactar contratos con proveedores, clientes o aliados estratégicos. ✔ Colaborar en auditorías internas para asegurar cumplimiento normativo. | D9: ✔ Abogado recibido. ✔ Perfil proactivo, con iniciativa y orientación a la resolución de problemas. ✔ Capacidad de investigación y actualización constante en normativa ✔ Buen nivel de redacción y comunicación. ✔ Conocimientos en Google Sheets y herramientas de visualización ✔ Ubicación: CABA - Monserrat. ✔ Esquema Presencial. | E9: ✔Anticipar y mitigar riesgos legales en operaciones digitales y logísticas. ✔Asegurar el cumplimiento normativo en un entorno de negocios dinámico. ✔Gestionar eficientemente procesos de cobranzas con impacto legal. ✔Adaptar marcos contractuales a nuevos modelos de negocio. | F9: ✔Análisis jurídico y pensamiento crítico. ✔Redacción técnica y contractual. ✔Proactividad en la gestión de riesgos. ✔Organización y seguimiento de casos. ✔Comunicación efectiva con áreas no legales. | G9: ✔ Prepaga de primer nivel ✔ Almuerzo en oficina sin costo ✔ Bonificación del 80% en SportClub ✔ Descuentos exclusivos en Samsung ✔ Club de beneficios | H9: =BASE!D9 -> Buenos Aires | I9: Híbrido | J9: =BASE!J9 -> 46097
A10: =BASE!A10 -> JOB-2025-000009 | B10: =BASE!B10 -> Analista de Finanzas y créditos | C10: ✔ Análisis de datos, generación de métricas y reportes orientado a dar soporte y mejora continua al equipo de Finanzas y Créditos con alta injerencia en el área de Administración. ✔ Será responsable del reporting con todo lo relacionado a Cobranzas y Pagos. ✔ Estructurará refinanciaciones a compradores, definiendo plazos, tasas e importes. ✔ Dará soporte al área de administración a través de creación de herramientas/planillas para robustecer procesos y mejorar los mismos. ✔ Deberá poder entender y manejar sistemas de gestión contables para estructurar información y armar KPIs. | D10: ✔ Perfil proactivo, con ganas de aprender, iniciativa y orientación a la resolución de problemas. ✔ Conocimientos en Google Sheets y herramientas de visualización | E10: ✔Optimizar la gestión de cobranzas y pagos mediante análisis financiero. ✔Diseñar propuestas de refinanciación viables según perfil del cliente. ✔Generar información confiable para la toma de decisiones crediticias. ✔Mejorar procesos administrativos a través de herramientas de gestión. | F10: ✔Análisis financiero y manejo de datos. ✔Pensamiento analítico y resolución de problemas. ✔Organización y atención al detalle. ✔Manejo de sistemas contables y financieros. ✔Proactividad para la mejora de procesos. | G10: ✔ Prepaga de primer nivel ✔ Almuerzo en oficina sin costo ✔ Bonificación del 80% en SportClub ✔ Descuentos exclusivos en Samsung ✔ Club de beneficios | H10: =BASE!D10 -> Buenos Aires | I10: Híbrido | J10: =BASE!J10 -> 46082
A11: =BASE!A11 -> JOB-2025-000010 | B11: =BASE!B11 -> Gerente de Unidad Financiera | C11: Gestión integral del P&L del área ✓ Responsable de la facturación (top line) y de los costos asociados a dCP. Crecimiento comercial ✓ Incrementar el uso de la plataforma por parte de clientes actuales (ej. mayor cantidad de pagos por cliente). ✓ Impulsar productos existentes como anticipos y refinanciaciones comerciales. ✓ Liderar el desarrollo e implementación de nuevos productos financieros. Desarrollo de procesos ✓ Definir y estructurar procesos comerciales, de atención al cliente y de backoffice. ✓ Trabajar en coordinación con áreas transversales (Producto, Tecnología, Operaciones y Atención al Cliente). Relaciones internas clave ✓ Administración y Finanzas, para procesos internos. ✓ Planificación, Soporte y Gestión, Atención al Cliente y Transporte. ✓ Desarrollo Tecnológico (equipo de Producto y de Desarrollo). | D11: ✔ Experiencia senior (idealmente 10+ años en fintech, banca, pagos digitales, o negocios con fuerte componente financiero). ✔Capacidad probada de manejar un P&L. ✔Mentalidad emprendedora, con foco en crecimiento, desarrollo comercial y escalabilidad de procesos. ✔Habilidad para trabajar en un ecosistema de stakeholders múltiples (producto, tecnología, comercial, atención). ✔Alta orientación a resultados, con track record en lanzamiento y escalada de productos financieros. ✔Buen entendimiento de productos como factoring, lending, pagos B2B y otros instrumentos financieros. | E11: ✔Gestionar el P&L del área, asegurando el cumplimiento de objetivos de facturación y control de costos. ✔Impulsar el crecimiento comercial mediante el uso de la plataforma y el desarrollo de productos financieros. ✔Diseñar e implementar procesos comerciales, operativos y de atención al cliente. ✔Liderar iniciativas transversales junto a Producto, Tecnología y Operaciones. | F11: ✔Visión estratégica y orientación a resultados. ✔Liderazgo y gestión de equipos. ✔Desarrollo de negocio y productos financieros. ✔Mejora de procesos y coordinación interáreas. ✔Análisis financiero y toma de decisiones. | G11: ✔ Prepaga de primer nivel ✔ Almuerzo en oficina sin costo ✔ Bonificación del 80% en SportClub ✔ Descuentos exclusivos en Samsung ✔ Club de beneficios ✔Cochera sin costo | H11: =BASE!D11 -> Buenos Aires | I11: Híbrido | J11: =BASE!J11 -> 46097
A12: =BASE!A12 -> JOB-2025-000011 | B12: =BASE!B12 -> Analista de Operaciones Comerciales | C12: ✔ Relevar y documentar procesos comerciales actuales, identificando oportunidades de optimización. ✔ Diseñar e implementar mejoras en los flujos y herramientas de gestión comercial (CRM, reportes, tableros, etc.). ✔ Extraer y limpiar datos de diversas fuentes (SQL, Excel, sistemas internos). ✔ Construir dashboards e informes en Power BI u otras herramientas de visualización. ✔ Diseñar y mantener indicadores clave (KPIs) que midan la efectividad y rentabilidad de las acciones comerciales. ✔ Analizar tendencias y comportamientos del negocio para generar insights que impacten en la estrategia comercial. ✔ Dar soporte analítico a las unidades de negocio, asegurando la consistencia de la información. | D12: ✔ Graduados de las carreras de Ingeniería Industrial. Adm de empresas, Adm Agropecuaria, similares. ✔ Manejo de Google Sheets, SQL y Power BI. ✔ Interés en la innovación tecnológica y la automatización de procesos. ✔ Actitud proactiva y resolutiva, con orientación a resultados. | E12: ✔Analizar y optimizar los procesos comerciales para mejorar la eficiencia operativa. ✔Transformar datos en información accionable para la toma de decisiones. ✔Diseñar y monitorear KPIs que permitan evaluar la performance del negocio. ✔Brindar soporte analítico a las distintas unidades comerciales. | F12: ✔Pensamiento analítico y orientación a resultados. ✔Manejo de herramientas de análisis de datos (SQL, Excel, BI). ✔Mejora de procesos y gestión de indicadores. ✔Capacidad de organización y trabajo transversal. ✔Comunicación efectiva para la interpretación de insights. | G12: ✔ Prepaga de primer nivel ✔ Almuerzo en oficina sin costo ✔ Bonificación del 80% en SportClub ✔ Descuentos exclusivos en Samsung ✔ Club de beneficios | H12: =BASE!D12 -> Buenos Aires | I12: Híbrido | J12: =BASE!J12 -> 46097
A13: =BASE!A13 -> JOB-2025-000012 | B13: =BASE!B13 -> Analista Contable SR | C13: ✔ Gestionar la operatoria administrativa diaria del área, asegurando orden y seguimiento de los distintos procesos. ✔ Registrar asientos contables y mantener la información contable actualizada. ✔ Realizar conciliaciones de cuentas contables y bancarias, identificando y siguiendo partidas pendientes. ✔ Analizar información contable y financiera, detectando desvíos y oportunidades de mejora. ✔ Llevar de manera metódica y organizada las partidas conciliatorias y reportes en Google Sheets. ✔ Administrar y dar seguimiento a temas vinculados a: ● Flota de la empresa ● Suministros ● Pagos y cobros ● Inversiones y otros procesos administrativos del sector | D13: ✔ Estudiante de la carrera de Contador. ✔ Manejo de Google Sheets, ✔Capacidad para trabajar de forma colaborativa, interactuando con distintos equipos ✔Perfil orientado a la mejora continua ✔Pensamiento lógico, analítico y resolutivo | F13: Analitico ,Comunicación Efectiva,Escucha Activa | G13: ✔ Prepaga de primer nivel ✔ Almuerzo en oficina sin costo ✔ Bonificación del 80% en SportClub ✔ Descuentos exclusivos en Samsung ✔ Club de beneficios | H13: =BASE!D13 -> Buenos Aires | I13: Híbrido | J13: =BASE!J13 -> 46002
A14: =BASE!A14 -> JOB-2025-000013 | B14: =BASE!B14 -> Analista de At. al Cliente | H14: =BASE!D14 -> Buenos Aires | I14: Hibrido | J14: =BASE!J14 -> 46082
A15: =BASE!A15 -> JOB-2025-000014 | B15: =BASE!B15 -> Analista de Logistica | H15: =BASE!D15 -> Buenos Aires | I15: Hibrido | J15: =BASE!J15 -> 46082
A16: =BASE!A16 -> JOB-2025-000015 | B16: =BASE!B16 -> Pasante Machine Learning | H16: =BASE!D16 -> Buenos Aires | I16: Hibrido | J16: =BASE!J16 -> 46082
A17: =BASE!A17 -> JOB-2025-000016 | B17: =BASE!B17 -> Regional Comercial | C17: ✔ Liderar el proceso de compra y venta de hacienda: Serás el punto clave en todo el proceso, desde el contacto inicial hasta la entrega final, gestionando la logística con eficiencia y asegurando que todo funcione sin problemas. ✔ Desarrollar tu zona de influencia: Serás responsable de identificar nuevas oportunidades y expandir nuestra red de clientes, contactando a aquellos que ya están en nuestros prospectos y abriendo nuevas tranqueras. ✔ Cultivar relaciones sólidas: Mantendrás una relación cercana y continua con nuestros clientes, entendiendo sus necesidades y asegurando que cada interacción resulte en una venta exitosa. ✔ Gestión eficiente del sistema: Mantendrás nuestra base de datos actualizada, asegurando que la información sea precisa y que nuestros procesos sean ágiles y efectivos. ✔ Participación activa en marketing: Serás nuestros ojos y oídos en el terreno, siendo una pieza clave en la organización y coordinación de eventos promocionales, ayudándonos a posicionarnos como líderes en el mercado. | D17: ✔ Experiencia mínima de 2 años en comercialización de hacienda bovina (gordos, invernada, cría). ✔ Sólidos conocimientos en ganadería bovina, tipos de categorías, plazos y condiciones de operación. ✔ Perfil comercial proactivo, con excelente manejo de relaciones interpersonales. ✔ Capacidad para detectar oportunidades de negocio, fidelizar clientes y generar nuevos vínculos comerciales. ✔ Conocimiento del mercado ganadero, operadores, consignatarias y zonas de producción. ✔ Autonomía para la gestión comercial integral: desde la captación de operaciones hasta el cierre y seguimiento. ✔ Disponibilidad para viajar. ✔ Se valora cartera de clientes activa o red de contactos en el sector. | E17: ✔ Desarrollar y expandir la cartera de clientes en su zona. ✔ Impulsar la adopción de soluciones digitales en el sector ganadero. ✔ Gestionar de punta a punta las operaciones comerciales. ✔ Generar relaciones de confianza con productores y clientes. ✔ Contribuir al posicionamiento de la compañía en el mercado regional. | F17: ✔Perfil comercial con orientación a resultados. ✔Capacidad de negociación y cierre. ✔Autonomía y proactividad. ✔Buen manejo de relaciones interpersonales. ✔Manejo de herramientas digitales. ✔Conocimiento del mercado ganadero (Excluyente) | H17: Buenos Aires - Pergamino / Rojas | I17: Híbrido | J17: =BASE!J17 -> 46097
A18: =BASE!A18 -> JOB-2025-000017 | B18: =BASE!B18 -> Regional Comercial | C18: ✔ Liderar el proceso de compra y venta de hacienda: Serás el punto clave en todo el proceso, desde el contacto inicial hasta la entrega final, gestionando la logística con eficiencia y asegurando que todo funcione sin problemas. ✔ Desarrollar tu zona de influencia: Serás responsable de identificar nuevas oportunidades y expandir nuestra red de clientes, contactando a aquellos que ya están en nuestros prospectos y abriendo nuevas tranqueras. ✔ Cultivar relaciones sólidas: Mantendrás una relación cercana y continua con nuestros clientes, entendiendo sus necesidades y asegurando que cada interacción resulte en una venta exitosa. ✔ Gestión eficiente del sistema: Mantendrás nuestra base de datos actualizada, asegurando que la información sea precisa y que nuestros procesos sean ágiles y efectivos. ✔ Participación activa en marketing: Serás nuestros ojos y oídos en el terreno, siendo una pieza clave en la organización y coordinación de eventos promocionales, ayudándonos a posicionarnos como líderes en el mercado. | D18: ✔ Experiencia mínima de 2 años en comercialización de hacienda bovina (gordos, invernada, cría). Sólidos conocimientos en ganadería bovina, tipos de categorías, plazos y condiciones de operación. ✔ Perfil comercial proactivo, con excelente manejo de relaciones interpersonales. ✔ Capacidad para detectar oportunidades de negocio, fidelizar clientes y generar nuevos vínculos comerciales. ✔ Conocimiento del mercado ganadero, operadores, consignatarias y zonas de producción. ✔ Autonomía para la gestión comercial integral: desde la captación de operaciones hasta el cierre y seguimiento. ✔ Disponibilidad para viajar. ✔ Se valora cartera de clientes activa o red de contactos en el sector. | E18: ✔ Desarrollar y expandir la cartera de clientes en su zona. ✔ Impulsar la adopción de soluciones digitales en el sector ganadero. ✔ Gestionar de punta a punta las operaciones comerciales. ✔ Generar relaciones de confianza con productores y clientes. ✔ Contribuir al posicionamiento de la compañía en el mercado regional. | F18: ✔Perfil comercial con orientación a resultados. ✔Capacidad de negociación y cierre. ✔Autonomía y proactividad. ✔Buen manejo de relaciones interpersonales. ✔Manejo de herramientas digitales. ✔Conocimiento del mercado ganadero (Excluyente) | H18: Santa Fe - 9 de Julio | I18: Híbrido | J18: =BASE!J18 -> 46097
A19: =BASE!A19 -> JOB-2025-000018 | B19: =BASE!B19 -> Regional Comercial | C19: ✔ Liderar el proceso de compra y venta de hacienda: Serás el punto clave en todo el proceso, desde el contacto inicial hasta la entrega final, gestionando la logística con eficiencia y asegurando que todo funcione sin problemas. ✔ Desarrollar tu zona de influencia: Serás responsable de identificar nuevas oportunidades y expandir nuestra red de clientes, contactando a aquellos que ya están en nuestros prospectos y abriendo nuevas tranqueras. ✔ Cultivar relaciones sólidas: Mantendrás una relación cercana y continua con nuestros clientes, entendiendo sus necesidades y asegurando que cada interacción resulte en una venta exitosa. ✔ Gestión eficiente del sistema: Mantendrás nuestra base de datos actualizada, asegurando que la información sea precisa y que nuestros procesos sean ágiles y efectivos. ✔ Participación activa en marketing: Serás nuestros ojos y oídos en el terreno, siendo una pieza clave en la organización y coordinación de eventos promocionales, ayudándonos a posicionarnos como líderes en el mercado. | D19: ✔ Experiencia mínima de 2 años en comercialización de hacienda bovina (gordos, invernada, cría). Sólidos conocimientos en ganadería bovina, tipos de categorías, plazos y condiciones de operación. ✔ Perfil comercial proactivo, con excelente manejo de relaciones interpersonales. ✔ Capacidad para detectar oportunidades de negocio, fidelizar clientes y generar nuevos vínculos comerciales. ✔ Conocimiento del mercado ganadero, operadores, consignatarias y zonas de producción. ✔ Autonomía para la gestión comercial integral: desde la captación de operaciones hasta el cierre y seguimiento. ✔ Disponibilidad para viajar. ✔ Se valora cartera de clientes activa o red de contactos en el sector. | E19: ✔ Desarrollar y expandir la cartera de clientes en su zona. ✔ Impulsar la adopción de soluciones digitales en el sector ganadero. ✔ Gestionar de punta a punta las operaciones comerciales. ✔ Generar relaciones de confianza con productores y clientes. ✔ Contribuir al posicionamiento de la compañía en el mercado regional. | F19: ✔Perfil comercial con orientación a resultados. ✔Capacidad de negociación y cierre. ✔Autonomía y proactividad. ✔Buen manejo de relaciones interpersonales. ✔Manejo de herramientas digitales. ✔Conocimiento del mercado ganadero (Excluyente) | H19: Entre Rios - Villaguay | I19: Híbrido | J19: =BASE!J20 -> 46097
A20: =BASE!A20 -> JOB-2025-000019 | B20: =BASE!B20 -> Regional Comercial | C20: ✔ Liderar el proceso de compra y venta de hacienda: Serás el punto clave en todo el proceso, desde el contacto inicial hasta la entrega final, gestionando la logística con eficiencia y asegurando que todo funcione sin problemas. ✔ Desarrollar tu zona de influencia: Serás responsable de identificar nuevas oportunidades y expandir nuestra red de clientes, contactando a aquellos que ya están en nuestros prospectos y abriendo nuevas tranqueras. ✔ Cultivar relaciones sólidas: Mantendrás una relación cercana y continua con nuestros clientes, entendiendo sus necesidades y asegurando que cada interacción resulte en una venta exitosa. ✔ Gestión eficiente del sistema: Mantendrás nuestra base de datos actualizada, asegurando que la información sea precisa y que nuestros procesos sean ágiles y efectivos. ✔ Participación activa en marketing: Serás nuestros ojos y oídos en el terreno, siendo una pieza clave en la organización y coordinación de eventos promocionales, ayudándonos a posicionarnos como líderes en el mercado. | D20: ✔ Experiencia mínima de 2 años en comercialización de hacienda bovina (gordos, invernada, cría). Sólidos conocimientos en ganadería bovina, tipos de categorías, plazos y condiciones de operación. ✔ Perfil comercial proactivo, con excelente manejo de relaciones interpersonales. ✔ Capacidad para detectar oportunidades de negocio, fidelizar clientes y generar nuevos vínculos comerciales. ✔ Conocimiento del mercado ganadero, operadores, consignatarias y zonas de producción. ✔ Autonomía para la gestión comercial integral: desde la captación de operaciones hasta el cierre y seguimiento. ✔ Disponibilidad para viajar. ✔ Se valora cartera de clientes activa o red de contactos en el sector. | E20: ✔ Desarrollar y expandir la cartera de clientes en su zona. ✔ Impulsar la adopción de soluciones digitales en el sector ganadero. ✔ Gestionar de punta a punta las operaciones comerciales. ✔ Generar relaciones de confianza con productores y clientes. ✔ Contribuir al posicionamiento de la compañía en el mercado regional. | F20: ✔Perfil comercial con orientación a resultados. ✔Capacidad de negociación y cierre. ✔Autonomía y proactividad. ✔Buen manejo de relaciones interpersonales. ✔Manejo de herramientas digitales. ✔Conocimiento del mercado ganadero (Excluyente) | H20: Entre Rios - Gualeguay | I20: Híbrido | J20: =BASE!J21 -> 46097
A21: =BASE!A21 -> JOB-2025-000020 | B21: =BASE!B21 -> Regional Comercial | C21: ✔ Liderar el proceso de compra y venta de hacienda: Serás el punto clave en todo el proceso, desde el contacto inicial hasta la entrega final, gestionando la logística con eficiencia y asegurando que todo funcione sin problemas. ✔ Desarrollar tu zona de influencia: Serás responsable de identificar nuevas oportunidades y expandir nuestra red de clientes, contactando a aquellos que ya están en nuestros prospectos y abriendo nuevas tranqueras. ✔ Cultivar relaciones sólidas: Mantendrás una relación cercana y continua con nuestros clientes, entendiendo sus necesidades y asegurando que cada interacción resulte en una venta exitosa. ✔ Gestión eficiente del sistema: Mantendrás nuestra base de datos actualizada, asegurando que la información sea precisa y que nuestros procesos sean ágiles y efectivos. ✔ Participación activa en marketing: Serás nuestros ojos y oídos en el terreno, siendo una pieza clave en la organización y coordinación de eventos promocionales, ayudándonos a posicionarnos como líderes en el mercado. | D21: ✔ Experiencia mínima de 2 años en comercialización de hacienda bovina (gordos, invernada, cría). Sólidos conocimientos en ganadería bovina, tipos de categorías, plazos y condiciones de operación. ✔ Perfil comercial proactivo, con excelente manejo de relaciones interpersonales. ✔ Capacidad para detectar oportunidades de negocio, fidelizar clientes y generar nuevos vínculos comerciales. ✔ Conocimiento del mercado ganadero, operadores, consignatarias y zonas de producción. ✔ Autonomía para la gestión comercial integral: desde la captación de operaciones hasta el cierre y seguimiento. ✔ Disponibilidad para viajar. ✔ Se valora cartera de clientes activa o red de contactos en el sector. | E21: ✔ Desarrollar y expandir la cartera de clientes en su zona. ✔ Impulsar la adopción de soluciones digitales en el sector ganadero. ✔ Gestionar de punta a punta las operaciones comerciales. ✔ Generar relaciones de confianza con productores y clientes. ✔ Contribuir al posicionamiento de la compañía en el mercado regional. | F21: ✔Perfil comercial con orientación a resultados. ✔Capacidad de negociación y cierre. ✔Autonomía y proactividad. ✔Buen manejo de relaciones interpersonales. ✔Manejo de herramientas digitales. ✔Conocimiento del mercado ganadero (Excluyente) | H21: Cordoba - Rio Cuarto | I21: Híbrido | J21: =#REF! -> #REF!
A22: =BASE!A22 -> JOB-2025-000021 | B22: =BASE!B22 -> Regional Comercial | C22: ✔ Liderar el proceso de compra y venta de hacienda: Serás el punto clave en todo el proceso, desde el contacto inicial hasta la entrega final, gestionando la logística con eficiencia y asegurando que todo funcione sin problemas. ✔ Desarrollar tu zona de influencia: Serás responsable de identificar nuevas oportunidades y expandir nuestra red de clientes, contactando a aquellos que ya están en nuestros prospectos y abriendo nuevas tranqueras. ✔ Cultivar relaciones sólidas: Mantendrás una relación cercana y continua con nuestros clientes, entendiendo sus necesidades y asegurando que cada interacción resulte en una venta exitosa. ✔ Gestión eficiente del sistema: Mantendrás nuestra base de datos actualizada, asegurando que la información sea precisa y que nuestros procesos sean ágiles y efectivos. ✔ Participación activa en marketing: Serás nuestros ojos y oídos en el terreno, siendo una pieza clave en la organización y coordinación de eventos promocionales, ayudándonos a posicionarnos como líderes en el mercado. | D22: ✔ Experiencia mínima de 2 años en comercialización de hacienda bovina (gordos, invernada, cría). Sólidos conocimientos en ganadería bovina, tipos de categorías, plazos y condiciones de operación. ✔ Perfil comercial proactivo, con excelente manejo de relaciones interpersonales. ✔ Capacidad para detectar oportunidades de negocio, fidelizar clientes y generar nuevos vínculos comerciales. ✔ Conocimiento del mercado ganadero, operadores, consignatarias y zonas de producción. ✔ Autonomía para la gestión comercial integral: desde la captación de operaciones hasta el cierre y seguimiento. ✔ Disponibilidad para viajar. ✔ Se valora cartera de clientes activa o red de contactos en el sector. | E22: ✔ Desarrollar y expandir la cartera de clientes en su zona. ✔ Impulsar la adopción de soluciones digitales en el sector ganadero. ✔ Gestionar de punta a punta las operaciones comerciales. ✔ Generar relaciones de confianza con productores y clientes. ✔ Contribuir al posicionamiento de la compañía en el mercado regional. | F22: ✔Perfil comercial con orientación a resultados. ✔Capacidad de negociación y cierre. ✔Autonomía y proactividad. ✔Buen manejo de relaciones interpersonales. ✔Manejo de herramientas digitales. ✔Conocimiento del mercado ganadero (Excluyente) | H22: Salta - Anta | I22: Híbrido | J22: =BASE!J22 -> 46097
A23: =BASE!A23 -> JOB-2025-000022 | B23: =BASE!B23 -> Regional Comercial | C23: ✔ Liderar el proceso de compra y venta de hacienda: Serás el punto clave en todo el proceso, desde el contacto inicial hasta la entrega final, gestionando la logística con eficiencia y asegurando que todo funcione sin problemas. ✔ Desarrollar tu zona de influencia: Serás responsable de identificar nuevas oportunidades y expandir nuestra red de clientes, contactando a aquellos que ya están en nuestros prospectos y abriendo nuevas tranqueras. ✔ Cultivar relaciones sólidas: Mantendrás una relación cercana y continua con nuestros clientes, entendiendo sus necesidades y asegurando que cada interacción resulte en una venta exitosa. ✔ Gestión eficiente del sistema: Mantendrás nuestra base de datos actualizada, asegurando que la información sea precisa y que nuestros procesos sean ágiles y efectivos. ✔ Participación activa en marketing: Serás nuestros ojos y oídos en el terreno, siendo una pieza clave en la organización y coordinación de eventos promocionales, ayudándonos a posicionarnos como líderes en el mercado. | D23: ✔ Experiencia mínima de 2 años en comercialización de hacienda bovina (gordos, invernada, cría). Sólidos conocimientos en ganadería bovina, tipos de categorías, plazos y condiciones de operación. ✔ Perfil comercial proactivo, con excelente manejo de relaciones interpersonales. ✔ Capacidad para detectar oportunidades de negocio, fidelizar clientes y generar nuevos vínculos comerciales. ✔ Conocimiento del mercado ganadero, operadores, consignatarias y zonas de producción. ✔ Autonomía para la gestión comercial integral: desde la captación de operaciones hasta el cierre y seguimiento. ✔ Disponibilidad para viajar. ✔ Se valora cartera de clientes activa o red de contactos en el sector. | E23: ✔ Desarrollar y expandir la cartera de clientes en su zona. ✔ Impulsar la adopción de soluciones digitales en el sector ganadero. ✔ Gestionar de punta a punta las operaciones comerciales. ✔ Generar relaciones de confianza con productores y clientes. ✔ Contribuir al posicionamiento de la compañía en el mercado regional. | F23: ✔Perfil comercial con orientación a resultados. ✔Capacidad de negociación y cierre. ✔Autonomía y proactividad. ✔Buen manejo de relaciones interpersonales. ✔Manejo de herramientas digitales. ✔Conocimiento del mercado ganadero (Excluyente) | H23: Formosa - Patiño | I23: Híbrido | J23: =BASE!J23 -> 46097
A24: =BASE!A24 -> JOB-2025-000023 | B24: =BASE!B24 -> Regional Comercial | C24: ✔ Liderar el proceso de compra y venta de hacienda: Serás el punto clave en todo el proceso, desde el contacto inicial hasta la entrega final, gestionando la logística con eficiencia y asegurando que todo funcione sin problemas. ✔ Desarrollar tu zona de influencia: Serás responsable de identificar nuevas oportunidades y expandir nuestra red de clientes, contactando a aquellos que ya están en nuestros prospectos y abriendo nuevas tranqueras. ✔ Cultivar relaciones sólidas: Mantendrás una relación cercana y continua con nuestros clientes, entendiendo sus necesidades y asegurando que cada interacción resulte en una venta exitosa. ✔ Gestión eficiente del sistema: Mantendrás nuestra base de datos actualizada, asegurando que la información sea precisa y que nuestros procesos sean ágiles y efectivos. ✔ Participación activa en marketing: Serás nuestros ojos y oídos en el terreno, siendo una pieza clave en la organización y coordinación de eventos promocionales, ayudándonos a posicionarnos como líderes en el mercado. | D24: ✔ Experiencia mínima de 2 años en comercialización de hacienda bovina (gordos, invernada, cría). Sólidos conocimientos en ganadería bovina, tipos de categorías, plazos y condiciones de operación. ✔ Perfil comercial proactivo, con excelente manejo de relaciones interpersonales. ✔ Capacidad para detectar oportunidades de negocio, fidelizar clientes y generar nuevos vínculos comerciales. ✔ Conocimiento del mercado ganadero, operadores, consignatarias y zonas de producción. ✔ Autonomía para la gestión comercial integral: desde la captación de operaciones hasta el cierre y seguimiento. ✔ Disponibilidad para viajar. ✔ Se valora cartera de clientes activa o red de contactos en el sector. | E24: ✔ Desarrollar y expandir la cartera de clientes en su zona. ✔ Impulsar la adopción de soluciones digitales en el sector ganadero. ✔ Gestionar de punta a punta las operaciones comerciales. ✔ Generar relaciones de confianza con productores y clientes. ✔ Contribuir al posicionamiento de la compañía en el mercado regional. | F24: ✔Perfil comercial con orientación a resultados. ✔Capacidad de negociación y cierre. ✔Autonomía y proactividad. ✔Buen manejo de relaciones interpersonales. ✔Manejo de herramientas digitales. ✔Conocimiento del mercado ganadero (Excluyente) | H24: San Luis - Gobenador Dupuy | I24: Híbrido | J24: =BASE!J24 -> 46097
A25: =BASE!A25 -> JOB-2025-000024 | B25: =BASE!B25 -> Regional Comercial | C25: ✔ Liderar el proceso de compra y venta de hacienda: Serás el punto clave en todo el proceso, desde el contacto inicial hasta la entrega final, gestionando la logística con eficiencia y asegurando que todo funcione sin problemas. ✔ Desarrollar tu zona de influencia: Serás responsable de identificar nuevas oportunidades y expandir nuestra red de clientes, contactando a aquellos que ya están en nuestros prospectos y abriendo nuevas tranqueras. ✔ Cultivar relaciones sólidas: Mantendrás una relación cercana y continua con nuestros clientes, entendiendo sus necesidades y asegurando que cada interacción resulte en una venta exitosa. ✔ Gestión eficiente del sistema: Mantendrás nuestra base de datos actualizada, asegurando que la información sea precisa y que nuestros procesos sean ágiles y efectivos. ✔ Participación activa en marketing: Serás nuestros ojos y oídos en el terreno, siendo una pieza clave en la organización y coordinación de eventos promocionales, ayudándonos a posicionarnos como líderes en el mercado. | D25: ✔ Experiencia mínima de 2 años en comercialización de hacienda bovina (gordos, invernada, cría). Sólidos conocimientos en ganadería bovina, tipos de categorías, plazos y condiciones de operación. ✔ Perfil comercial proactivo, con excelente manejo de relaciones interpersonales. ✔ Capacidad para detectar oportunidades de negocio, fidelizar clientes y generar nuevos vínculos comerciales. ✔ Conocimiento del mercado ganadero, operadores, consignatarias y zonas de producción. ✔ Autonomía para la gestión comercial integral: desde la captación de operaciones hasta el cierre y seguimiento. ✔ Disponibilidad para viajar. ✔ Se valora cartera de clientes activa o red de contactos en el sector. | E25: ✔ Desarrollar y expandir la cartera de clientes en su zona. ✔ Impulsar la adopción de soluciones digitales en el sector ganadero. ✔ Gestionar de punta a punta las operaciones comerciales. ✔ Generar relaciones de confianza con productores y clientes. ✔ Contribuir al posicionamiento de la compañía en el mercado regional. | F25: ✔Perfil comercial con orientación a resultados. ✔Capacidad de negociación y cierre. ✔Autonomía y proactividad. ✔Buen manejo de relaciones interpersonales. ✔Manejo de herramientas digitales. ✔Conocimiento del mercado ganadero (Excluyente) | H25: Buenos Aires - Tapalque / Bolivar | I25: Híbrido | J25: =BASE!J25 -> 46097
A26: =BASE!A26 -> JOB-2025-000025 | B26: =BASE!B26 -> Regional Comercial | C26: ✔ Liderar el proceso de compra y venta de hacienda: Serás el punto clave en todo el proceso, desde el contacto inicial hasta la entrega final, gestionando la logística con eficiencia y asegurando que todo funcione sin problemas. ✔ Desarrollar tu zona de influencia: Serás responsable de identificar nuevas oportunidades y expandir nuestra red de clientes, contactando a aquellos que ya están en nuestros prospectos y abriendo nuevas tranqueras. ✔ Cultivar relaciones sólidas: Mantendrás una relación cercana y continua con nuestros clientes, entendiendo sus necesidades y asegurando que cada interacción resulte en una venta exitosa. ✔ Gestión eficiente del sistema: Mantendrás nuestra base de datos actualizada, asegurando que la información sea precisa y que nuestros procesos sean ágiles y efectivos. ✔ Participación activa en marketing: Serás nuestros ojos y oídos en el terreno, siendo una pieza clave en la organización y coordinación de eventos promocionales, ayudándonos a posicionarnos como líderes en el mercado. | D26: ✔ Experiencia mínima de 2 años en comercialización de hacienda bovina (gordos, invernada, cría). Sólidos conocimientos en ganadería bovina, tipos de categorías, plazos y condiciones de operación. ✔ Perfil comercial proactivo, con excelente manejo de relaciones interpersonales. ✔ Capacidad para detectar oportunidades de negocio, fidelizar clientes y generar nuevos vínculos comerciales. ✔ Conocimiento del mercado ganadero, operadores, consignatarias y zonas de producción. ✔ Autonomía para la gestión comercial integral: desde la captación de operaciones hasta el cierre y seguimiento. ✔ Disponibilidad para viajar. ✔ Se valora cartera de clientes activa o red de contactos en el sector. | E26: ✔ Desarrollar y expandir la cartera de clientes en su zona. ✔ Impulsar la adopción de soluciones digitales en el sector ganadero. ✔ Gestionar de punta a punta las operaciones comerciales. ✔ Generar relaciones de confianza con productores y clientes. ✔ Contribuir al posicionamiento de la compañía en el mercado regional. | F26: ✔Perfil comercial con orientación a resultados. ✔Capacidad de negociación y cierre. ✔Autonomía y proactividad. ✔Buen manejo de relaciones interpersonales. ✔Manejo de herramientas digitales. ✔Conocimiento del mercado ganadero (Excluyente) | H26: Buenos Aires - Azul | I26: Híbrido | J26: =BASE!J26 -> 46097
